Workbook

Sheet Sommaire
A1: FICHES TECHNIQUES – MENU ANNUEL EHPAD / FAM
A2: Cliquer sur le nom d'une fiche pour l'ouvrir. Modes : CBT – cuisson de nuit (four vapeur 12-18 h) ; Sous vide basse température ; Cuisson traditionnelle ; Préparation froide.
A3: Sur chaque fiche : saisir le nombre de portions à produire (B24) et, si besoin, le grammage (B23) et les prix unitaires (colonne E) ; les quantités de production (colonne C) et les coûts se recalculent.
A5: Catégorie | B5: Fiche | C5: Mode de cuisson | D5: Titre de la fiche | E5: Nb de fois au menu 2026
A6: Entrée | B6: Salade verte | C6: Préparation froide | D6: Salade verte | E6: 92
A7: Entrée | B7: Potage de légumes | C7: CBT – cuisson de nuit | D7: Potage de légumes cuisson de nuit | E7: 44
A8: Entrée | B8: Potage de féculents | C8: CBT – cuisson de nuit | D8: Potage de féculents cuisson de nuit | E8: 14
A9: Entrée | B9: Taboulé | C9: Préparation froide | D9: Taboulé | E9: 38
A10: Entrée | B10: Feuilleté | C10: Cuisson traditionnelle | D10: Feuilleté | E10: 29
A11: Entrée | B11: Salade d'endives | C11: Préparation froide | D11: Salade d'endives | E11: 21
A12: Entrée | B12: Salade d'endives aux noix | C12: Préparation froide | D12: Salade d'endives aux noix | E12: 2
A13: Entrée | B13: Endives au bleu et aux noix | C13: Préparation froide | D13: Endives au bleu et aux noix | E13: 2
A14: Entrée | B14: Salade de riz | C14: Préparation froide | D14: Salade de riz | E14: 20
A15: Entrée | B15: Betteraves vinaigrette | C15: Sous vide basse température | D15: Betteraves vinaigrette sous vide basse température | E15: 35
A16: Entrée | B16: Salade de betteraves et maïs | C16: Sous vide basse température | D16: Salade de betteraves et maïs sous vide basse température | E16: 4
A17: Entrée | B17: Salade mexicaine | C17: Préparation froide | D17: Salade mexicaine | E17: 14
... A279: Dessert | B279: Tarte aux framboises | C279: Cuisson traditionnelle | D279: Tarte aux framboises | E279: 1
A280: Autres fiches du chef | B280: Joue de boeuf | C280: CBT – fiche originale du chef | D280: Joue de bœuf aubergine et chorizo cuisson de nuit
A281: Autres fiches du chef | B281: Haricots rouges | C281: CBT – fiche originale du chef | D281: Haricots Rouges Chili cuisson de nuit
A282: Autres fiches du chef | B282: Chili-viande à part | C282: CBT – fiche originale du chef | D282: Haricots Rouges - Chili- viande à part cuisson de nuit
A283: Autres fiches du chef | B283: COCO-Catalans | C283: CBT – fiche originale du chef | D283: Coco Catalans cuisson de nuit
A284: Autres fiches du chef | B284: Pois Chiches | C284: CBT – fiche originale du chef | D284: Pois chiches cuisson de nuit

Sheet Paramètres
A1: PARAMÈTRES DE PRODUCTION
A2: Nombre de portions de la recette de base | B2: 70 | C2: Les quantités de la colonne B de chaque fiche sont calculées pour ce nombre de portions.
A3: Effectif maison de retraite (EHPAD) | B3: 70 | C3: À CONFIRMER – valeur provisoire, à saisir.
A4: Effectif FAM | B4: 40 | C4: Saisi d'après les indications du chef.
A5: Nombre de portions à produire (total) | B5: =B3+B4 -> 110 | C5: Utilisé par défaut en B24 de chaque fiche (modifiable fiche par fiche).
A7: Cellules jaunes = à saisir. Le total se recalcule automatiquement.

Sheet Cadencier
A1: CADENCIER – CATALOGUE DES PRODUITS
A2: Prix de base = estimation grossiste collectivité 2026 (HT, par unité d'achat), à remplacer par vos prix facture. Saisir le prix facture (colonne G, jaune), la date et le fournisseur : le prix retenu (J) bascule automatiquement sur le prix facture et met à jour toutes les fiches.
A4: Code | B4: Famille | C4: Produit | D4: Unité | E4: Conditionnement | F4: Prix de base estimé HT (€/unité) | G4: Prix facture HT (€/unité) | H4: Date facture | I4: Fournisseur | J4: Prix retenu (€/unité) | K4: Nb de fiches | L4: Observations
A5: VIA-001 | B5: Viandes | C5: Agneau haché 15 % MG | D5: Kg | E5: barquette 2,5 kg | F5: 12.5 | J5: =IF(G5<>"",G5,F5) -> 12.5 | K5: 2
A6: VIA-002 | B6: Viandes | C6: Boulettes de bœuf crues surgelées 30 g | D6: Kg | E6: carton 5 kg | F6: 8.5 | J6: =IF(G6<>"",G6,F6) -> 8.5 | K6: 1
A7: VIA-003 | B7: Viandes | C7: Brochettes de bœuf 100 g | D7: Kg | E7: barquette 5 kg (50 pièces) | F7: 14 | J7: =IF(G7<>"",G7,F7) -> 14 | K7: 1
A8: VIA-004 | B8: Viandes | C8: Bœuf haché 15 % MG frais | D8: Kg | E8: barquette 2,5 kg | F8: 9.5 | J8: =IF(G8<>"",G8,F8) -> 9.5 | K8: 9
A9: VIA-005 | B9: Viandes | C9: Bœuf haché 15 % MG surgelé | D9: Kg | E9: sachet 2,5 kg | F9: 8.5 | J9: =IF(G9<>"",G9,F9) -> 8.5 | K9: 1
A10: VIA-006 | B10: Viandes | C10: Cuisses de lapin surgelées 180 g | D10: Kg | E10: carton 5 kg | F10: 9.5 | J10: =IF(G10<>"",G10,F10) -> 9.5 | K10: 1
A11: VIA-007 | B11: Viandes | C11: Égrené de bœuf | D11: Kg | E11: sachet 2,5 kg | F11: 8 | J11: =IF(G11<>"",G11,F11) -> 8 | K11: 0
A12: VIA-008 | B12: Viandes | C12: Escalopes de porc 110 g | D12: Kg | E12: barquette 5 kg | F12: 8 | J12: =IF(G12<>"",G12,F12) -> 8 | K12: 1
A13: VIA-009 | B13: Viandes | C13: Escalopes de veau 110 g | D13: Kg | E13: barquette 5 kg | F13: 18 | J13: =IF(G13<>"",G13,F13) -> 18 | K13: 1
A14: VIA-010 | B14: Viandes | C14: Filet mignon de porc paré | D14: Kg | E14: sous vide 5 kg | F14: 9.5 | J14: =IF(G14<>"",G14,F14) -> 9.5 | K14: 1
A15: VIA-011 | B15: Viandes | C15: Gigot d'agneau désossé ficelé | D15: Kg | E15: sous vide 2-2,5 kg | F15: 15.5 | J15: =IF(G15<>"",G15,F15) -> 15.5 | K15: 1
A16: VIA-012 | B16: Viandes | C16: Joue de bœuf parée | D16: Kg | E16: sous vide 3 kg | F16: 10.5 | J16: =IF(G16<>"",G16,F16) -> 10.5 | K16: 0
... A132: BOF-025 | B132: Produits laitiers et œufs (BOF) | C132: Tome fraîche de l'Aubrac | D132: Kg | E132: pièce 2 kg | F132: 12 | J132: =IF(G132<>"",G132,F132) -> 12 | K132: 1
A133: BOF-026 | B133: Produits laitiers et œufs (BOF) | C133: Œufs coquille calibre moyen | D133: Kg | E133: plateau 30 x 6 (≈ 0.18 €/pièce) | F133: 3 | J133: =IF(G133<>"",G133,F133) -> 3 | K133: 1 | L133: Prix converti au kg sur la base de 60 g par pièce
A134: BOF-027 | B134: Produits laitiers et œufs (BOF) | C134: Œufs durs écalés pasteurisés | D134: Kg | E134: seau 75 pièces (≈ 0.28 €/pièce) | F134: 5.6 | J134: =IF(G134<>"",G134,F134) -> 5.6 | K134: 12 | L134: Prix converti au kg sur la base de 50 g par pièce
A135: BOF-028 | B135: Produits laitiers et œufs (BOF) | C135: Œufs entiers liquides pasteurisés | D135: L | E135: brique 1 L x 6 | F135: 3.8 | J135: =IF(G135<>"",G135,F135) -> 3.8 | K135: 21
A136: BOF-029 | B136: Produits laitiers et œufs (BOF) | C136: Yaourt nature | D136: Kg | E136: seau 5 kg | F136: 2.5 | J136: =IF(G136<>"",G136,F136) -> 2.5 | K136: 1
A137: FLF-001 | B137: Fruits et légumes frais | C137: Ail frais | D137: Kg | E137: filet 1 kg | F137: 6 | J137: =IF(G137<>"",G137,F137) -> 6 | K137: 0
A138: FLF-002 | B138: Fruits et légumes frais | C138: Ananas frais | D138: Kg | E138: carton 8 pièces (≈ 2.80 €/pièce) | F138: 1.87 | J138: =IF(G138<>"",G138,F138) -> 1.87 | K138: 1 | L138: Prix converti au kg sur la base de 1500 g par pièce
A139: FLF-003 | B139: Fruits et légumes frais | C139: Asperges blanches fraîches épluchées | D139: Kg | E139: botte 1 kg | F139: 9 | J139: =IF(G139<>"",G139,F139) -> 9 | K139: 1
A140: FLF-004 | B140: Fruits et légumes frais | C140: Aubergines fraîches | D140: Kg | E140: colis 5 kg | F140: 2.6 | J140: =IF(G140<>"",G140,F140) -> 2.6 | K140: 2
A141: FLF-005 | B141: Fruits et légumes frais | C141: Avocats | D141: Kg | E141: colis 12 pièces (≈ 1.10 €/pièce) | F141: 5.5 | J141: =IF(G141<>"",G141,F141) -> 5.5 | K141: 1 | L141: Prix converti au kg sur la base de 200 g par pièce
A142: FLF-006 | B142: Fruits et légumes frais | C142: Bananes | D142: Kg | E142: carton 18 kg | F142: 1.6 | J142: =IF(G142<>"",G142,F142) -> 1.6 | K142: 1
A143: FLF-007 | B143: Fruits et légumes frais | C143: Basilic frais (botte) | D143: Kg | E143: botte (≈ 1.60 €/pièce) | F143: 32 | J143: =IF(G143<>"",G143,F143) -> 32 | K143: 2 | L143: Prix converti au kg sur la base de 50 g par pièce
A144: FLF-008 | B144: Fruits et légumes frais | C144: Betteraves rouges crues | D144: Kg | E144: sac 5 kg | F144: 1.4 | J144: =IF(G144<>"",G144,F144) -> 1.4 | K144: 2
A145: FLF-009 | B145: Fruits et légumes frais | C145: Carottes bâtonnets 4ème gamme | D145: Kg | E145: sachet 2,5 kg | F145: 3.2 | J145: =IF(G145<>"",G145,F145) -> 3.2 | K145: 1
A146: FLF-010 | B146: Fruits et légumes frais | C146: Carottes fraîches | D146: Kg | E146: sac 10 kg | F146: 1 | J146: =IF(G146<>"",G146,F146) -> 1 | K146: 3
A147: FLF-011 | B147: Fruits et légumes frais | C147: Carottes râpées 4ème gamme | D147: Kg | E147: sachet 2,5 kg | F147: 3.2 | J147: =IF(G147<>"",G147,F147) -> 3.2 | K147: 2
A148: FLF-012 | B148: Fruits et légumes frais | C148: Céleri-rave (boule) | D148: Kg | E148: colis 10 kg | F148: 1.6 | J148: =IF(G148<>"",G148,F148) -> 1.6 | K148: 1
A149: FLF-013 | B149: Fruits et légumes frais | C149: Céleri-rave râpé 4ème gamme | D149: Kg | E149: sachet 2,5 kg | F149: 3.5 | J149: =IF(G149<>"",G149,F149) -> 3.5 | K149: 1
A150: FLF-014 | B150: Fruits et légumes frais | C150: Chou blanc | D150: Kg | E150: colis 10 kg | F150: 1 | J150: =IF(G150<>"",G150,F150) -> 1 | K150: 1
A151: FLF-015 | B151: Fruits et légumes frais | C151: Chou chinois | D151: Kg | E151: colis 8 kg | F151: 1.9 | J151: =IF(G151<>"",G151,F151) -> 1.9 | K151: 1
A152: FLF-016 | B152: Fruits et légumes frais | C152: Chou rouge râpé 4ème gamme | D152: Kg | E152: sachet 2,5 kg | F152: 3.2 | J152: =IF(G152<>"",G152,F152) -> 3.2 | K152: 1
A153: FLF-017 | B153: Fruits et légumes frais | C153: Chou vert frisé | D153: Kg | E153: colis 10 kg | F153: 1.3 | J153: =IF(G153<>"",G153,F153) -> 1.3 | K153: 1
A154: FLF-018 | B154: Fruits et légumes frais | C154: Citrons jaunes | D154: Kg | E154: colis 10 kg | F154: 2.2 | J154: =IF(G154<>"",G154,F154) -> 2.2 | K154: 13
A155: FLF-019 | B155: Fruits et légumes frais | C155: Citrons verts | D155: Kg | E155: colis 4,5 kg | F155: 3.5 | J155: =IF(G155<>"",G155,F155) -> 3.5 | K155: 1
A156: FLF-020 | B156: Fruits et légumes frais | C156: Concombres | D156: Kg | E156: colis 12 pièces (≈ 0.90 €/pièce) | F156: 2.25 | J156: =IF(G156<>"",G156,F156) -> 2.25 | K156: 5 | L156: Prix converti au kg sur la base de 400 g par pièce
...

Sheet Correspondance
A1: Correspondance entre les intitulés utilisés dans les fiches et les produits du cadencier (le prix est repris du cadencier par formule). Modifier le code (colonne B) pour rattacher un intitulé à un autre produit.
A2: Intitulé dans les fiches | B2: Code produit | C2: Produit du cadencier | D2: Prix retenu (€/unité)
A3: Agneau ou bœuf haché | B3: VIA-001 | C3: =IFERROR(INDEX(Cadencier!$C$5:$C$441,MATCH(B3,Cadencier!$A$5:$A$441,0)),"code inconnu") -> Agneau haché 15 % MG | D3: =IFERROR(INDEX(Cadencier!$J$5:$J$441,MATCH(B3,Cadencier!$A$5:$A$441,0)),0) -> 12.5
A4: Aiguillettes de poulet | B4: VOL-001 | C4: =IFERROR(INDEX(Cadencier!$C$5:$C$441,MATCH(B4,Cadencier!$A$5:$A$441,0)),"code inconnu") -> Aiguillettes de poulet | D4: =IFERROR(INDEX(Cadencier!$J$5:$J$441,MATCH(B4,Cadencier!$A$5:$A$441,0)),0) -> 10.5
A5: Ail | B5: FLF-001 | C5: =IFERROR(INDEX(Cadencier!$C$5:$C$441,MATCH(B5,Cadencier!$A$5:$A$441,0)),"code inconnu") -> Ail frais | D5: =IFERROR(INDEX(Cadencier!$J$5:$J$441,MATCH(B5,Cadencier!$A$5:$A$441,0)),0) -> 6
A6: Ail surgelé | B6: SUR-001 | C6: =IFERROR(INDEX(Cadencier!$C$5:$C$441,MATCH(B6,Cadencier!$A$5:$A$441,0)),"code inconnu") -> Ail surgelé | D6: =IFERROR(INDEX(Cadencier!$J$5:$J$441,MATCH(B6,Cadencier!$A$5:$A$441,0)),0) -> 5.5
A7: Ananas frais (ou 4ème gamme) | B7: FLF-002 | C7: =IFERROR(INDEX(Cadencier!$C$5:$C$441,MATCH(B7,Cadencier!$A$5:$A$441,0)),"code inconnu") -> Ananas frais | D7: =IFERROR(INDEX(Cadencier!$J$5:$J$441,MATCH(B7,Cadencier!$A$5:$A$441,0)),0) -> 1.87
A8: Anchois en filets (ou pâte d'anchois) | B8: CON-001 | C8: =IFERROR(INDEX(Cadencier!$C$5:$C$441,MATCH(B8,Cadencier!$A$5:$A$441,0)),"code inconnu") -> Anchois en filets (à l'huile) | D8: =IFERROR(INDEX(Cadencier!$J$5:$J$441,MATCH(B8,Cadencier!$A$5:$A$441,0)),0) -> 22
A9: Andouillettes AAAAA 150 g (environ 65 pièces) | B9: CHA-001 | C9: =IFERROR(INDEX(Cadencier!$C$5:$C$441,MATCH(B9,Cadencier!$A$5:$A$441,0)),"code inconnu") -> Andouillettes AAAAA 150 g | D9: =IFERROR(INDEX(Cadencier!$J$5:$J$441,MATCH(B9,Cadencier!$A$5:$A$441,0)),0) -> 11
A10: Aneth ciselé surgelé | B10: SUR-002 | C10: =IFERROR(INDEX(Cadencier!$C$5:$C$441,MATCH(B10,Cadencier!$A$5:$A$441,0)),"code inconnu") -> Aneth ciselé surgelé | D10: =IFERROR(INDEX(Cadencier!$J$5:$J$441,MATCH(B10,Cadencier!$A$5:$A$441,0)),0) -> 14
A11: Aneth PM | B11: SUR-002 | C11: =IFERROR(INDEX(Cadencier!$C$5:$C$441,MATCH(B11,Cadencier!$A$5:$A$441,0)),"code inconnu") -> Aneth ciselé surgelé | D11: =IFERROR(INDEX(Cadencier!$J$5:$J$441,MATCH(B11,Cadencier!$A$5:$A$441,0)),0) -> 14
A12: Aneth surgelé | B12: SUR-002 | C12: =IFERROR(INDEX(Cadencier!$C$5:$C$441,MATCH(B12,Cadencier!$A$5:$A$441,0)),"code inconnu") -> Aneth ciselé surgelé | D12: =IFERROR(INDEX(Cadencier!$J$5:$J$441,MATCH(B12,Cadencier!$A$5:$A$441,0)),0) -> 14
A13: Anneaux de calamar surgelés | B13: POI-001 | C13: =IFERROR(INDEX(Cadencier!$C$5:$C$441,MATCH(B13,Cadencier!$A$5:$A$441,0)),"code inconnu") -> Anneaux de calamar surgelés | D13: =IFERROR(INDEX(Cadencier!$J$5:$J$441,MATCH(B13,Cadencier!$A$5:$A$441,0)),0) -> 8.5
A14: Anneaux ou lanières de calamars surgelés | B14: POI-001 | C14: =IFERROR(INDEX(Cadencier!$C$5:$C$441,MATCH(B14,Cadencier!$A$5:$A$441,0)),"code inconnu") -> Anneaux de calamar surgelés | D14: =IFERROR(INDEX(Cadencier!$J$5:$J$441,MATCH(B14,Cadencier!$A$5:$A$441,0)),0) -> 8.5
... A753: Œufs liquides pasteurisés | B753: BOF-028 | C753: =IFERROR(INDEX(Cadencier!$C$5:$C$441,MATCH(B753,Cadencier!$A$5:$A$441,0)),"code inconnu") -> Œufs entiers liquides pasteurisés | D753: =IFERROR(INDEX(Cadencier!$J$5:$J$441,MATCH(B753,Cadencier!$A$5:$A$441,0)),0) -> 3.8

Sheet Menu → fiches
A1: Semaine | B1: Jour | C1: Service | D1: Entrée (menu) | E1: Fiche entrée | F1: Plat (menu) | G1: Fiche plat | H1: Garniture (menu) | I1: Fiche garniture | J1: Dessert (menu) | K1: Fiche dessert
A2: semaine 1 | B2: Lundi | C2: Midi | D2: Taboulé | E2: Taboulé | F2: Paupiette de volaile | G2: Paupiette de volaille | H2: Choux fleur | I2: Chou-fleur persillé | J2: Fruit
A3: semaine 1 | B3: Lundi | C3: Soir | D3: Mache | E3: Salade de mâche | F3: Jambon Blanc | G3: Jambon blanc | H3: pomme de terre rissolées | I3: Pommes de terre rissolées | J3: Fruit
A4: semaine 1 | B4: Mardi | C4: Midi | D4: Poireau en salade | E4: Poireaux vinaigrette | F4: tartiflette | G4: Tartiflette | J4: Dessert
A5: semaine 1 | B5: Mardi | C5: Soir | D5: Potage de Légumes | E5: Potage de légumes | F5: œuf mayonnaise | G5: Œuf mayonnaise | H5: salsifi | I5: Salsifis | J5: Fruit
A6: semaine 1 | B6: Mercredi | C6: Midi | D6: Salade de lentille | E6: Salade de lentilles | F6: Suprême de volaille | G6: Suprême de volaille | H6: Haricots verts | I6: Salade de haricots verts | J6: Fruit
A7: semaine 1 | B7: Mercredi | C7: Soir | D7: Velouté de cépes chataigne | E7: Velouté de cèpes et châtaignes | F7: Croustade escargots | G7: Croustade d'escargots | H7: Duo de carottes | I7: Carottes Vichy | J7: Entremets croustillant chocolat | K7: Entremets croustillant chocolat
A8: semaine 1 | B8: Jeudi | C8: Midi | D8: salade périgoudine | E8: Salade périgourdine | F8: Filet mignon au cidre | G8: Filet mignon de porc au cidre | H8: Risotto | I8: Risotto | J8: Entremet vanille Fruit rouge | K8: Entremets vanille fruits rouges
A9: semaine 1 | B9: Jeudi | C9: Soir | D9: Soupe de poisson | E9: Soupe de poisson | F9: Feuilleté | G9: Feuilleté | H9: Crumble de légumes | I9: Crumble de légumes | J9: Fruit
A10: semaine 1 | B10: Vendredi | C10: Midi | D10: Paté aux olives | E10: Pâté aux olives | F10: Pavé de poisson | G10: Pavé de poisson sauce beurre blanc | H10: Riz | I10: Riz pilaf | J10: Fruit
A11: semaine 1 | B11: Vendredi | C11: Soir | D11: Terrine de légumes | E11: Terrine de légumes | F11: Qunelle de volaille | G11: Quenelles de volaille sauce | H11: carottes | I11: Carottes Vichy | J11: Fruit
A12: semaine 1 | B12: Samedi | C12: Midi | D12: salade de Pâtess | E12: Salade de pâtes | F12: Roti de porc | G12: Rôti de porc | H12: Choux rpmanesco | I12: Chou romanesco | J12: Fruit
A13: semaine 1 | B13: Samedi | C13: Soir | D13: Potage de Légumes | E13: Potage de légumes | F13: lasagne au bœuf | G13: Lasagnes au bœuf | J13: Fruit
A14: semaine 1 | B14: Dimanche | C14: Midi | D14: salade verte | E14: Salade verte | F14: escalope milanaise | G14: Escalope viennoise | H14: semoule | I14: Semoule | J14: Dessert
A15: semaine 1 | B15: Dimanche | C15: Soir | D15: carottes rapées | E15: Carottes râpées | F15: dos de colin meunière | G15: Dos de colin meunière | H15: rapé de pomme de terre | I15: Râpé de pommes de terre | J15: Fruit
A16: semaine 2 | B16: Lundi | C16: Midi | D16: Salade verte | E16: Salade verte | F16: Sauté de Lapin | G16: Sauté de lapin | H16: Choux de Bruxelles | I16: Choux de Bruxelles | J16: Fruit
A17: semaine 2 | B17: Lundi | C17: Soir | D17: Salade de Perles | E17: Salade de perles | F17: Endives au Jambon | G17: Endives au jambon | J17: Fruit
A18: semaine 2 | B18: Mardi | C18: Midi | D18: Salade Coleslow | E18: Coleslaw | F18: Croziflette | G18: Croziflette | J18: Dessert
A19: semaine 2 | B19: Mardi | C19: Soir | D19: Potage de Légumes | E19: Potage de légumes | F19: Chipolatas | G19: Chipolatas | H19: Haricots blanc | I19: Haricots blancs | J19: Fruit
A20: semaine 2 | B20: Mercredi | C20: Midi | D20: Taboulé | E20: Taboulé | F20: Escalope dinde | G20: Escalope de dinde | H20: gratin de potimarron | I20: Gratin de potimarron | J20: Fruit
A21: semaine 2 | B21: Mercredi | C21: Soir | D21: Macédoine de Légumes | E21: Macédoine mayonnaise | F21: Raviolis | G21: Raviolis | J21: Fruit
A22: semaine 2 | B22: Jeudi | C22: Midi | D22: Salade de Chou Chinois | E22: Salade de chou chinois | F22: Saucisse | G22: Saucisse de Toulouse | H22: Aligot | I22: Aligot | J22: Fruit
A23: semaine 2 | B23: Jeudi | C23: Soir | D23: Potage de Féculents | E23: Potage de féculents | F23: Œuf béchamel | G23: Œufs durs sauce béchamel | H23: Haricots beurre | I23: Haricots beurre | J23: Fruit
A24: semaine 2 | B24: Vendredi | C24: Midi | D24: Mousse de Canard | E24: Mousse de canard | F24: Saumon | G24: Pavé de saumon | H24: Chou Romanesco | I24: Chou romanesco | J24: Fruit
A25: semaine 2 | B25: Vendredi | C25: Soir | D25: Salade d'endives | E25: Salade d'endives | F25: Chili con carne | G25: Chili con carne | J25: Fruit
A26: semaine 2 | B26: Samedi | C26: Midi | D26: Carottes Rapées | E26: Carottes râpées | F26: Flecque | G26: Flammekueche | J26: Fruit
A27: semaine 2 | B27: Samedi | C27: Soir | D27: Potage de Légumes | E27: Potage de légumes | F27: Pates Carbonara | G27: Pâtes carbonara | J27: Fruit
A28: semaine 2 | B28: Dimanche | C28: Midi | D28: Salade verte | E28: Salade verte | F28: Rôti de Veau | G28: Rôti de veau | H28: Lentilles | I28: Lentilles | J28: Dessert
A29: semaine 2 | B29: Dimanche | C29: Soir | D29: Salade de Riz | E29: Salade de riz | F29: maquereaux | G29: Maquereaux à la moutarde | H29: Poelée de légumes | I29: Poêlée de légumes | J29: Fruit
A30: semaine 3 | B30: Lundi | C30: Midi | D30: Tranche de Jambon Cru | E30: Jambon cru | F30: Pavé de Poisson | G30: Pavé de poisson sauce beurre blanc | H30: Epinards à la crème | I30: Épinards à la crème | J30: Fruit
A31: semaine 3 | B31: Lundi | C31: Soir | D31: Poireaux vinaigrette | E31: Poireaux vinaigrette | F31: Escalope viennoise | G31: Escalope viennoise | H31: Riz | I31: Riz pilaf | J31: Fruit
A32: semaine 3 | B32: Mardi | C32: Midi | D32: Avocat | E32: Avocat vinaigrette ou mayonnaise | F32: Pot au feu | G32: Pot-au-feu | J32: Dessert
A33: semaine 3 | B33: Mardi | C33: Soir | D33: Potage de Légumes | E33: Potage de légumes | F33: Pâtess Bolognaise | G33: Pâtes bolognaise | J33: Fruit
A34: semaine 3 | B34: Mercredi | C34: Midi | D34: Feuilleté | E34: Feuilleté | F34: Sûprèmes de Volaille | G34: Suprême de volaille | H34: Petit Pois | I34: Petits pois | J34: Fruit
A35: semaine 3 | B35: Mercredi | C35: Soir | D35: Taboulé | E35: Taboulé | F35: Langue de Bœuf Sauce Piquante | G35: Langue de bœuf sauce piquante | H35: Côtes de Blette | I35: Côtes de blettes | J35: Fruit
A36: semaine 3 | B36: Jeudi | C36: Midi | D36: Salade d'Endives | E36: Salade d'endives | F36: Choucroute | G36: Choucroute garnie | J36: Fruit
A37: semaine 3 | B37: Jeudi | C37: Soir | D37: Potage de Féculents | E37: Potage de féculents | F37: Mortadelle | G37: Mortadelle | H37: Carottes Persillées | I37: Carottes Vichy | J37: Fruit
A38: semaine 3 | B38: Vendredi | C38: Midi | D38: Salade Mexicaine | E38: Salade mexicaine | F38: Gratin de poisson | G38: Gratin de poisson | H38: Haricots vert | I38: Haricots verts | J38: Fruit
A39: semaine 3 | B39: Vendredi | C39: Soir | D39: Salade verte | E39: Salade verte | F39: Quiche | G39: Quiche lorraine | H39: Pâtess | I39: Pâtes au beurre | J39: Fruit
A40: semaine 3 | B40: Samedi | C40: Midi | D40: Pamplemousse | E40: Pamplemousse | F40: Escalope de Veau | G40: Escalope de veau | H40: Pomme de Terre boulangère | I40: Pommes de terre boulangère | J40: Fruit
...

Sheet T° cuisson de nuit
A1: Cuisson longues (12H00 à 18H00)
A2: Vapeur ou thermoplongeur
B3: Produits | C3: Remarques
A4: 95°C | B4: Agrumes | C4: Sirop à 15 (1kg de sucre pour 0,5L eau) - Temps de cuisson des agrumes sous vide 5H00 minimum à 18H00
B5: Légumineuses
A6: 88°C | B6: Tête de veau
B7: Langue de Bœuf
B8: Pied de porc - veau
A9: 85°C | B9: Sauté de bœuf
B10: Sauté de mouton
B11: Ratatouille
B12: Legumes tajine
B13: Aubergines
B14: Cuisse de poule
B15: Paleron de bœuf
A16: 74°C | B16: Osso Bucco
B17: Blanquette de veau | C17: Débuter la cuisson à 85°C pendant 2H00
A18: 72°C | B18: Souris d'agneau | C18: Possibilité à 68°C
B19: Cuisses de canard entière | C19: Possibilité à 68°C
B20: Sauté d'agneau
A21: 70C | B21: Paleron de veau
A22: 65°C | B22: Rôti de veau bas carré
B23: Echine de porc | C23: Débuter cuisson par un pic (80°C ambiance -72°C à cœur)
A24: 62°C | B24: Ballotines de canard
B25: Ballotines épaules d'agneau | C25: A 65°C si un peu ferme

Sheet E-Salade verte
A1: Salade verte | E1: VP Théorique minimum | G1: Préparation froide Bac gastro + film, 0/+3°C Vinaigrette à part
E2: Liaison froide 0/+3°C
A3: Produits | B3: Qté recette base | C3: Qté production | D3: U | E3: PU | F3: Total €
A4: Salade verte (batavia, laitue ou frisée) | B4: 4.66 | C4: =B4/B$22*B$24 -> 7.3215497 | D4: Kg | E4: =IFERROR(INDEX(Correspondance!$D$2:$D$3000,MATCH(A4,Correspondance!$A$2:$A$3000,0)),0) -> 5.5 | F4: =C4*E4 -> 40.268523 | G4: Mode opératoire : Effeuiller et parer les salades, éliminer les feuilles abîmées et le trognon Décontamination : trempage 5 min en eau + désinfectant agréé, rinçage abondant à l'eau claire Essorer soigneusement, couper grossièrement Vinaigrette : délayer moutarde, sel, poivre, vinaigre, monter à l'huile, ajouter échalotes et ciboulette Conditionner la salade en bacs gastro filmés, vinaigrette à part en pot fermé Stocker à 0/+3°C, assaisonner au dernier moment au service Service en liaison froide, consommation dans les 24h
A5: Huile de tournesol | B5: 0.559 | C5: =B5/B$22*B$24 -> 0.87827174 | D5: L | E5: =IFERROR(INDEX(Correspondance!$D$2:$D$3000,MATCH(A5,Correspondance!$A$2:$A$3000,0)),0) -> 2.2 | F5: =C5*E5 -> 1.9321978
A6: Vinaigre de vin | B6: 0.186 | C6: =B6/B$22*B$24 -> 0.29223353 | D6: L | E6: =IFERROR(INDEX(Correspondance!$D$2:$D$3000,MATCH(A6,Correspondance!$A$2:$A$3000,0)),0) -> 1.5 | F6: =C6*E6 -> 0.43835029
A7: Moutarde de Dijon | B7: 0.075 | C7: =B7/B$22*B$24 -> 0.1178361 | D7: Kg | E7: =IFERROR(INDEX(Correspondance!$D$2:$D$3000,MATCH(A7,Correspondance!$A$2:$A$3000,0)),0) -> 9 | F7: =C7*E7 -> 1.0605249
A8: Échalotes ciselées surgelées | B8: 0.093 | C8: =B8/B$22*B$24 -> 0.14611676 | D8: Kg | E8: =IFERROR(INDEX(Correspondance!$D$2:$D$3000,MATCH(A8,Correspondance!$A$2:$A$3000,0)),0) -> 4.5 | F8: =C8*E8 -> 0.65752544
A9: Sel fin | B9: 0.028 | C9: =B9/B$22*B$24 -> 0.043992144 | D9: Kg | E9: =IFERROR(INDEX(Correspondance!$D$2:$D$3000,MATCH(A9,Correspondance!$A$2:$A$3000,0)),0) -> 2 | F9: =C9*E9 -> 0.087984289
A10: Poivre PM | C10: =B10/B$22*B$24 -> 0 | D10: Kg | E10: =IFERROR(INDEX(Correspondance!$D$2:$D$3000,MATCH(A10,Correspondance!$A$2:$A$3000,0)),0) -> 18 | F10: =C10*E10 -> 0
A11: Ciboulette ciselée PM | C11: =B11/B$22*B$24 -> 0 | D11: Kg | E11: =IFERROR(INDEX(Correspondance!$D$2:$D$3000,MATCH(A11,Correspondance!$A$2:$A$3000,0)),0) -> 13 | F11: =C11*E11 -> 0
C12: =B12/B$22*B$24 -> 0 | E12: =IFERROR(INDEX(Correspondance!$D$2:$D$3000,MATCH(A12,Correspondance!$A$2:$A$3000,0)),0) -> 0 | F12: =C12*E12 -> 0
C13: =B13/B$22*B$24 -> 0 | E13: =IFERROR(INDEX(Correspondance!$D$2:$D$3000,MATCH(A13,Correspondance!$A$2:$A$3000,0)),0) -> 0 | F13: =C13*E13 -> 0
C14: =B14/B$22*B$24 -> 0 | E14: =IFERROR(INDEX(Correspondance!$D$2:$D$3000,MATCH(A14,Correspondance!$A$2:$A$3000,0)),0) -> 0 | F14: =C14*E14 -> 0
C15: =B15/B$22*B$24 -> 0 | E15: =IFERROR(INDEX(Correspondance!$D$2:$D$3000,MATCH(A15,Correspondance!$A$2:$A$3000,0)),0) -> 0 | F15: =C15*E15 -> 0
C16: =B16/B$22*B$24 -> 0 | E16: =IFERROR(INDEX(Correspondance!$D$2:$D$3000,MATCH(A16,Correspondance!$A$2:$A$3000,0)),0) -> 0 | F16: =C16*E16 -> 0
C17: =B17/B$22*B$24 -> 0 | E17: =IFERROR(INDEX(Correspondance!$D$2:$D$3000,MATCH(A17,Correspondance!$A$2:$A$3000,0)),0) -> 0 | F17: =C17*E17 -> 0
C18: =B18/B$22*B$24 -> 0 | E18: =IFERROR(INDEX(Correspondance!$D$2:$D$3000,MATCH(A18,Correspondance!$A$2:$A$3000,0)),0) -> 0 | F18: =C18*E18 -> 0
F19: =SUM(F4:F18) -> 44.445106
A20: Prix unitaire portion | B20: =F19/B24 -> 0.40404642
A21: Poids total ou ingrédient principal | B21: =SUM(B3:B18) -> 5.601
A22: Nombre portions recette base | B22: =B21/B23 -> 70.0125
A23: Poids net portions | B23: 0.08 | C23: Possibilité de saisir le grammage
A24: Nombre portions à produire | B24: =Paramètres!$B$5 -> 110 | C24: Effectif EHPAD + FAM (feuille Paramètres) – possibilité de saisir un autre nombre

Sheet E-Potage de légumes
A1: Potage de légumes cuisson de nuit | E1: VP Théorique minimum | G1: Cuisson 85°C four vapeur Bac gastro 1/1 avec couvercles sans trou Ou sauteuse fonction mijotage (compatible cuisson de nuit)
E2: > à 10 000
A3: Produits | B3: Qté recette base | C3: Qté production | D3: U | E3: PU | F3: Total €
A4: Poireaux rondelles surgelés | B4: 2.77 | C4: =B4/B$22*B$24 -> 4.3518624 | D4: Kg | E4: =IFERROR(INDEX(Correspondance!$D$2:$D$3000,MATCH(A4,Correspondance!$A$2:$A$3000,0)),0) -> 2.6 | F4: =C4*E4 -> 11.314842 | G4: Mode opératoire : Peser tous les ingrédients d'épicerie Répartir les légumes surgelés et les pommes de terre dans des bacs 1/1 (H15), 2 bacs maximum par recette Mouiller à l'eau, ajouter le fond de volaille, sel, poivre et le beurre, mélanger Ajouter un couvercle sans trou Cuisson : 85°C vapeur 12H00 minimum et 18H00 au maximum (programme Potage cuisson de nuit) Le lendemain : mixer finement au mixeur plongeant, ajouter la crème, rectifier l'assaisonnement Contrôle de la texture : allonger avec un peu de bouillon si nécessaire Refroidir en cellule (63°C à 10°C en moins de deux heures) pour une remise en T° différée ou maintenir en étuve ≥ 63°C pour un service en liaison chaude Sauteuse (compatible cuisson de nuit) : tous les ingrédients, couvrir, 85°C fonction mijotage 12H00 à 18H00, mixer le lendemain
A5: Pommes de terre cubes | B5: 2.77 | C5: =B5/B$22*B$24 -> 4.3518624 | D5: Kg | E5: =IFERROR(INDEX(Correspondance!$D$2:$D$3000,MATCH(A5,Correspondance!$A$2:$A$3000,0)),0) -> 2.2 | F5: =C5*E5 -> 9.5740973
A6: Carottes rondelles surgelées | B6: 1.85 | C6: =B6/B$22*B$24 -> 2.9064785 | D6: Kg | E6: =IFERROR(INDEX(Correspondance!$D$2:$D$3000,MATCH(A6,Correspondance!$A$2:$A$3000,0)),0) -> 1.8 | F6: =C6*E6 -> 5.2316613
A7: Navets cubes surgelés | B7: 0.923 | C7: =B7/B$22*B$24 -> 1.4500971 | D7: Kg | E7: =IFERROR(INDEX(Correspondance!$D$2:$D$3000,MATCH(A7,Correspondance!$A$2:$A$3000,0)),0) -> 2.2 | F7: =C7*E7 -> 3.1902137
A8: Oignons cubes surgelés | B8: 0.462 | C8: =B8/B$22*B$24 -> 0.7258341 | D8: Kg | E8: =IFERROR(INDEX(Correspondance!$D$2:$D$3000,MATCH(A8,Correspondance!$A$2:$A$3000,0)),0) -> 1.8 | F8: =C8*E8 -> 1.3065014
A9: Eau | B9: 7.39 | C9: =B9/B$22*B$24 -> 11.610203 | D9: L | E9: =IFERROR(INDEX(Correspondance!$D$2:$D$3000,MATCH(A9,Correspondance!$A$2:$A$3000,0)),0) -> 0 | F9: =C9*E9 -> 0
A10: Fond de volaille déshydraté | B10: 0.139 | C10: =B10/B$22*B$24 -> 0.21837866 | D10: Kg | E10: =IFERROR(INDEX(Correspondance!$D$2:$D$3000,MATCH(A10,Correspondance!$A$2:$A$3000,0)),0) -> 10 | F10: =C10*E10 -> 2.1837866
A11: Sel | B11: 0.092 | C11: =B11/B$22*B$24 -> 0.14453839 | D11: Kg | E11: =IFERROR(INDEX(Correspondance!$D$2:$D$3000,MATCH(A11,Correspondance!$A$2:$A$3000,0)),0) -> 2 | F11: =C11*E11 -> 0.28907678
A12: Poivre PM | C12: =B12/B$22*B$24 -> 0 | D12: Kg | E12: =IFERROR(INDEX(Correspondance!$D$2:$D$3000,MATCH(A12,Correspondance!$A$2:$A$3000,0)),0) -> 18 | F12: =C12*E12 -> 0
A13: Beurre | B13: 0.185 | C13: =B13/B$22*B$24 -> 0.29064785 | D13: Kg | E13: =IFERROR(INDEX(Correspondance!$D$2:$D$3000,MATCH(A13,Correspondance!$A$2:$A$3000,0)),0) -> 9 | F13: =C13*E13 -> 2.6158307
A14: Crème 35% | B14: 0.923 | C14: =B14/B$22*B$24 -> 1.4500971 | D14: L | E14: =IFERROR(INDEX(Correspondance!$D$2:$D$3000,MATCH(A14,Correspondance!$A$2:$A$3000,0)),0) -> 5.5 | F14: =C14*E14 -> 7.9755342
C15: =B15/B$22*B$24 -> 0 | E15: =IFERROR(INDEX(Correspondance!$D$2:$D$3000,MATCH(A15,Correspondance!$A$2:$A$3000,0)),0) -> 0 | F15: =C15*E15 -> 0
C16: =B16/B$22*B$24 -> 0 | E16: =IFERROR(INDEX(Correspondance!$D$2:$D$3000,MATCH(A16,Correspondance!$A$2:$A$3000,0)),0) -> 0 | F16: =C16*E16 -> 0
C17: =B17/B$22*B$24 -> 0 | E17: =IFERROR(INDEX(Correspondance!$D$2:$D$3000,MATCH(A17,Correspondance!$A$2:$A$3000,0)),0) -> 0 | F17: =C17*E17 -> 0
C18: =B18/B$22*B$24 -> 0 | E18: =IFERROR(INDEX(Correspondance!$D$2:$D$3000,MATCH(A18,Correspondance!$A$2:$A$3000,0)),0) -> 0 | F18: =C18*E18 -> 0
F19: =SUM(F4:F18) -> 43.681544
A20: Prix unitaire portion | B20: =F19/B24 -> 0.39710495
A21: Poids total ou ingrédient principal | B21: =SUM(B3:B18) -> 17.504
A22: Nombre portions recette base | B22: =B21/B23 -> 70.016
A23: Poids net portions | B23: 0.25 | C23: Possibilité de saisir le grammage
A24: Nombre portions à produire | B24: =Paramètres!$B$5 -> 110 | C24: Effectif EHPAD + FAM (feuille Paramètres) – possibilité de saisir un autre nombre

Sheet E-Potage de féculents
A1: Potage de féculents cuisson de nuit | E1: VP Théorique minimum | G1: Cuisson 95°C four vapeur Bac gastro 1/1 avec couvercles sans trou Ou sauteuse fonction mijotage (compatible cuisson de nuit)
E2: > à 10 000
A3: Produits | B3: Qté recette base | C3: Qté production | D3: U | E3: PU | F3: Total €
A4: Pois cassés secs | B4: 1.48 | C4: =B4/B$22*B$24 -> 2.3255814 | D4: Kg | E4: =IFERROR(INDEX(Correspondance!$D$2:$D$3000,MATCH(A4,Correspondance!$A$2:$A$3000,0)),0) -> 2.8 | F4: =C4*E4 -> 6.5116279 | G4: Mode opératoire : Peser tous les ingrédients d'épicerie, rincer les pois cassés Dans des bacs 1/1 (H15) mettre pois cassés, pommes de terre, légumes, lardons, aromates Mouiller à l'eau, ajouter le fond de volaille et le sel, mélanger Ajouter un couvercle sans trou Cuisson : 95°C vapeur 12H00 minimum et 18H00 au maximum Le lendemain : retirer le laurier et le thym, mixer finement, passer au chinois si besoin Ajouter la crème, rectifier sel et poivre, allonger au bouillon selon la texture souhaitée Refroidir en cellule (63°C à 10°C en moins de deux heures) pour une remise en T° différée ou maintenir en étuve ≥ 63°C pour un service en liaison chaude Sauteuse (compatible cuisson de nuit) : tous les ingrédients, couvrir, 95°C fonction mijotage 12H00 à 18H00, mixer le lendemain
A5: Pommes de terre cubes | B5: 1.97 | C5: =B5/B$22*B$24 -> 3.0955374 | D5: Kg | E5: =IFERROR(INDEX(Correspondance!$D$2:$D$3000,MATCH(A5,Correspondance!$A$2:$A$3000,0)),0) -> 2.2 | F5: =C5*E5 -> 6.8101823
A6: Carottes rondelles surgelées | B6: 0.986 | C6: =B6/B$22*B$24 -> 1.54934 | D6: Kg | E6: =IFERROR(INDEX(Correspondance!$D$2:$D$3000,MATCH(A6,Correspondance!$A$2:$A$3000,0)),0) -> 1.8 | F6: =C6*E6 -> 2.7888121
A7: Poireaux rondelles surgelés | B7: 0.986 | C7: =B7/B$22*B$24 -> 1.54934 | D7: Kg | E7: =IFERROR(INDEX(Correspondance!$D$2:$D$3000,MATCH(A7,Correspondance!$A$2:$A$3000,0)),0) -> 2.6 | F7: =C7*E7 -> 4.0282841
A8: Oignons cubes surgelés | B8: 0.493 | C8: =B8/B$22*B$24 -> 0.77467002 | D8: Kg | E8: =IFERROR(INDEX(Correspondance!$D$2:$D$3000,MATCH(A8,Correspondance!$A$2:$A$3000,0)),0) -> 1.8 | F8: =C8*E8 -> 1.394406
A9: Lardons fumés (facultatif) | B9: 0.493 | C9: =B9/B$22*B$24 -> 0.77467002 | D9: Kg | E9: =IFERROR(INDEX(Correspondance!$D$2:$D$3000,MATCH(A9,Correspondance!$A$2:$A$3000,0)),0) -> 8 | F9: =C9*E9 -> 6.1973602
A10: Eau | B10: 9.86 | C10: =B10/B$22*B$24 -> 15.4934 | D10: L | E10: =IFERROR(INDEX(Correspondance!$D$2:$D$3000,MATCH(A10,Correspondance!$A$2:$A$3000,0)),0) -> 0 | F10: =C10*E10 -> 0
A11: Fond de volaille déshydraté | B11: 0.148 | C11: =B11/B$22*B$24 -> 0.23255814 | D11: Kg | E11: =IFERROR(INDEX(Correspondance!$D$2:$D$3000,MATCH(A11,Correspondance!$A$2:$A$3000,0)),0) -> 10 | F11: =C11*E11 -> 2.3255814
A12: Sel | B12: 0.099 | C12: =B12/B$22*B$24 -> 0.15556254 | D12: Kg | E12: =IFERROR(INDEX(Correspondance!$D$2:$D$3000,MATCH(A12,Correspondance!$A$2:$A$3000,0)),0) -> 2 | F12: =C12*E12 -> 0.31112508
A13: Laurier - Thym PM | C13: =B13/B$22*B$24 -> 0 | D13: Kg | E13: =IFERROR(INDEX(Correspondance!$D$2:$D$3000,MATCH(A13,Correspondance!$A$2:$A$3000,0)),0) -> 16 | F13: =C13*E13 -> 0
A14: Crème 35% | B14: 0.986 | C14: =B14/B$22*B$24 -> 1.54934 | D14: L | E14: =IFERROR(INDEX(Correspondance!$D$2:$D$3000,MATCH(A14,Correspondance!$A$2:$A$3000,0)),0) -> 5.5 | F14: =C14*E14 -> 8.5213702
C15: =B15/B$22*B$24 -> 0 | E15: =IFERROR(INDEX(Correspondance!$D$2:$D$3000,MATCH(A15,Correspondance!$A$2:$A$3000,0)),0) -> 0 | F15: =C15*E15 -> 0
C16: =B16/B$22*B$24 -> 0 | E16: =IFERROR(INDEX(Correspondance!$D$2:$D$3000,MATCH(A16,Correspondance!$A$2:$A$3000,0)),0) -> 0 | F16: =C16*E16 -> 0
C17: =B17/B$22*B$24 -> 0 | E17: =IFERROR(INDEX(Correspondance!$D$2:$D$3000,MATCH(A17,Correspondance!$A$2:$A$3000,0)),0) -> 0 | F17: =C17*E17 -> 0
C18: =B18/B$22*B$24 -> 0 | E18: =IFERROR(INDEX(Correspondance!$D$2:$D$3000,MATCH(A18,Correspondance!$A$2:$A$3000,0)),0) -> 0 | F18: =C18*E18 -> 0
F19: =SUM(F4:F18) -> 38.888749
A20: Prix unitaire portion | B20: =F19/B24 -> 0.35353408
A21: Poids total ou ingrédient principal | B21: =SUM(B3:B18) -> 17.501
A22: Nombre portions recette base | B22: =B21/B23 -> 70.004
A23: Poids net portions | B23: 0.25 | C23: Possibilité de saisir le grammage
A24: Nombre portions à produire | B24: =Paramètres!$B$5 -> 110 | C24: Effectif EHPAD + FAM (feuille Paramètres) – possibilité de saisir un autre nombre

Sheet E-Taboulé
A1: Taboulé | E1: VP Théorique minimum | G1: Préparation froide Semoule hydratée à froid Bac gastro + film, 0/+3°C
E2: Liaison froide 0/+3°C
A3: Produits | B3: Qté recette base | C3: Qté production | D3: U | E3: PU | F3: Total €
A4: Semoule de blé moyenne | B4: 2.26 | C4: =B4/B$22*B$24 -> 3.5522093 | D4: Kg | E4: =IFERROR(INDEX(Correspondance!$D$2:$D$3000,MATCH(A4,Correspondance!$A$2:$A$3000,0)),0) -> 1.5 | F4: =C4*E4 -> 5.3283139 | G4: Mode opératoire : Peser tous les ingrédients d'épicerie Décontaminer et rincer tomates, concombre et menthe, tailler en petits dés Décongeler poivrons et oignons en enceinte réfrigérée la veille, bien égoutter Mélanger la semoule avec l'eau froide, le jus de citron, l'huile d'olive et le sel, laisser gonfler 30 min au froid Ajouter légumes, raisins secs, menthe et poivre, mélanger sans écraser Rectifier l'assaisonnement, laisser reposer 2 heures minimum à 0/+3°C Conditionner en bacs gastro filmés, étiqueter (date de fabrication) Service en liaison froide, consommation dans les 48h
A5: Eau froide | B5: 2.26 | C5: =B5/B$22*B$24 -> 3.5522093 | D5: L | E5: =IFERROR(INDEX(Correspondance!$D$2:$D$3000,MATCH(A5,Correspondance!$A$2:$A$3000,0)),0) -> 0 | F5: =C5*E5 -> 0
A6: Tomates en cubes | B6: 1.81 | C6: =B6/B$22*B$24 -> 2.844911 | D6: Kg | E6: =IFERROR(INDEX(Correspondance!$D$2:$D$3000,MATCH(A6,Correspondance!$A$2:$A$3000,0)),0) -> 1.5 | F6: =C6*E6 -> 4.2673665
A7: Concombre en dés | B7: 0.905 | C7: =B7/B$22*B$24 -> 1.4224555 | D7: Kg | E7: =IFERROR(INDEX(Correspondance!$D$2:$D$3000,MATCH(A7,Correspondance!$A$2:$A$3000,0)),0) -> 2.25 | F7: =C7*E7 -> 3.2005248
A8: Poivrons dés surgelés | B8: 0.452 | C8: =B8/B$22*B$24 -> 0.71044186 | D8: Kg | E8: =IFERROR(INDEX(Correspondance!$D$2:$D$3000,MATCH(A8,Correspondance!$A$2:$A$3000,0)),0) -> 3 | F8: =C8*E8 -> 2.1313256
A9: Oignons cubes surgelés | B9: 0.271 | C9: =B9/B$22*B$24 -> 0.42595076 | D9: Kg | E9: =IFERROR(INDEX(Correspondance!$D$2:$D$3000,MATCH(A9,Correspondance!$A$2:$A$3000,0)),0) -> 1.8 | F9: =C9*E9 -> 0.76671137
A10: Raisins secs | B10: 0.181 | C10: =B10/B$22*B$24 -> 0.2844911 | D10: Kg | E10: =IFERROR(INDEX(Correspondance!$D$2:$D$3000,MATCH(A10,Correspondance!$A$2:$A$3000,0)),0) -> 5 | F10: =C10*E10 -> 1.4224555
A11: Huile d'olive | B11: 0.543 | C11: =B11/B$22*B$24 -> 0.85347329 | D11: L | E11: =IFERROR(INDEX(Correspondance!$D$2:$D$3000,MATCH(A11,Correspondance!$A$2:$A$3000,0)),0) -> 7.5 | F11: =C11*E11 -> 6.4010497
A12: Jus de citron | B12: 0.362 | C12: =B12/B$22*B$24 -> 0.56898219 | D12: L | E12: =IFERROR(INDEX(Correspondance!$D$2:$D$3000,MATCH(A12,Correspondance!$A$2:$A$3000,0)),0) -> 2.5 | F12: =C12*E12 -> 1.4224555
A13: Sel | B13: 0.054 | C13: =B13/B$22*B$24 -> 0.084875797 | D13: Kg | E13: =IFERROR(INDEX(Correspondance!$D$2:$D$3000,MATCH(A13,Correspondance!$A$2:$A$3000,0)),0) -> 2 | F13: =C13*E13 -> 0.16975159
A14: Poivre PM | C14: =B14/B$22*B$24 -> 0 | D14: Kg | E14: =IFERROR(INDEX(Correspondance!$D$2:$D$3000,MATCH(A14,Correspondance!$A$2:$A$3000,0)),0) -> 18 | F14: =C14*E14 -> 0
A15: Menthe fraîche ciselée PM | C15: =B15/B$22*B$24 -> 0 | D15: Kg | E15: =IFERROR(INDEX(Correspondance!$D$2:$D$3000,MATCH(A15,Correspondance!$A$2:$A$3000,0)),0) -> 30 | F15: =C15*E15 -> 0
C16: =B16/B$22*B$24 -> 0 | E16: =IFERROR(INDEX(Correspondance!$D$2:$D$3000,MATCH(A16,Correspondance!$A$2:$A$3000,0)),0) -> 0 | F16: =C16*E16 -> 0
C17: =B17/B$22*B$24 -> 0 | E17: =IFERROR(INDEX(Correspondance!$D$2:$D$3000,MATCH(A17,Correspondance!$A$2:$A$3000,0)),0) -> 0 | F17: =C17*E17 -> 0
C18: =B18/B$22*B$24 -> 0 | E18: =IFERROR(INDEX(Correspondance!$D$2:$D$3000,MATCH(A18,Correspondance!$A$2:$A$3000,0)),0) -> 0 | F18: =C18*E18 -> 0
F19: =SUM(F4:F18) -> 25.109954
A20: Prix unitaire portion | B20: =F19/B24 -> 0.22827231
A21: Poids total ou ingrédient principal | B21: =SUM(B3:B18) -> 9.098
A22: Nombre portions recette base | B22: =B21/B23 -> 69.984615
A23: Poids net portions | B23: 0.13 | C23: Possibilité de saisir le grammage
A24: Nombre portions à produire | B24: =Paramètres!$B$5 -> 110 | C24: Effectif EHPAD + FAM (feuille Paramètres) – possibilité de saisir un autre nombre

Sheet E-Feuilleté
A1: Feuilleté | E1: VP Théorique minimum | G1: Four mixte 180°C chaleur sèche Plaques gastro + papier cuisson 15 à 20 min
E2: 63°C à cœur
A3: Produits | B3: Qté recette base | C3: Qté production | D3: U | E3: PU | F3: Total €
A4: Feuilletés jambon fromage surgelés (90 g pièce) | B4: 5.73 | C4: =B4/B$22*B$24 -> 9.0042857 | D4: Kg | E4: =IFERROR(INDEX(Correspondance!$D$2:$D$3000,MATCH(A4,Correspondance!$A$2:$A$3000,0)),0) -> 8.33 | F4: =C4*E4 -> 75.0057 | G4: Mode opératoire : Disposer les feuilletés surgelés sans décongélation sur plaques gastro recouvertes de papier cuisson, espacer Dorer au jaune d'œuf pasteurisé Four mixte 180°C chaleur sèche 15 à 20 min jusqu'à belle coloration Contrôle 63°C à cœur minimum, enregistrer la T° Maintenir en étuve ≥ 63°C jusqu'au service (30 min maximum pour garder le croustillant) Salade : décontaminer, rincer, essorer, préparer la vinaigrette Dressage : 1 feuilleté par personne sur lit de salade assaisonnée au dernier moment En remise en T° différée : refroidir en cellule puis régénérer 180°C 8 min, 63°C à cœur
A5: Salade frisée | B5: 1.37 | C5: =B5/B$22*B$24 -> 2.1528571 | D5: Kg | E5: =IFERROR(INDEX(Correspondance!$D$2:$D$3000,MATCH(A5,Correspondance!$A$2:$A$3000,0)),0) -> 3.6 | F5: =C5*E5 -> 7.7502857
A6: Huile de tournesol | B6: 0.273 | C6: =B6/B$22*B$24 -> 0.429 | D6: L | E6: =IFERROR(INDEX(Correspondance!$D$2:$D$3000,MATCH(A6,Correspondance!$A$2:$A$3000,0)),0) -> 2.2 | F6: =C6*E6 -> 0.9438
A7: Vinaigre de vin | B7: 0.091 | C7: =B7/B$22*B$24 -> 0.143 | D7: L | E7: =IFERROR(INDEX(Correspondance!$D$2:$D$3000,MATCH(A7,Correspondance!$A$2:$A$3000,0)),0) -> 1.5 | F7: =C7*E7 -> 0.2145
A8: Moutarde | B8: 0.036 | C8: =B8/B$22*B$24 -> 0.056571429 | D8: Kg | E8: =IFERROR(INDEX(Correspondance!$D$2:$D$3000,MATCH(A8,Correspondance!$A$2:$A$3000,0)),0) -> 9 | F8: =C8*E8 -> 0.50914286
A9: Sel | B9: 0.018 | C9: =B9/B$22*B$24 -> 0.028285714 | D9: Kg | E9: =IFERROR(INDEX(Correspondance!$D$2:$D$3000,MATCH(A9,Correspondance!$A$2:$A$3000,0)),0) -> 2 | F9: =C9*E9 -> 0.056571429
A10: Poivre PM | C10: =B10/B$22*B$24 -> 0 | D10: Kg | E10: =IFERROR(INDEX(Correspondance!$D$2:$D$3000,MATCH(A10,Correspondance!$A$2:$A$3000,0)),0) -> 18 | F10: =C10*E10 -> 0
A11: Jaune d'œuf pasteurisé (dorure) | B11: 0.182 | C11: =B11/B$22*B$24 -> 0.286 | D11: L | E11: =IFERROR(INDEX(Correspondance!$D$2:$D$3000,MATCH(A11,Correspondance!$A$2:$A$3000,0)),0) -> 6.5 | F11: =C11*E11 -> 1.859
C12: =B12/B$22*B$24 -> 0 | E12: =IFERROR(INDEX(Correspondance!$D$2:$D$3000,MATCH(A12,Correspondance!$A$2:$A$3000,0)),0) -> 0 | F12: =C12*E12 -> 0
C13: =B13/B$22*B$24 -> 0 | E13: =IFERROR(INDEX(Correspondance!$D$2:$D$3000,MATCH(A13,Correspondance!$A$2:$A$3000,0)),0) -> 0 | F13: =C13*E13 -> 0
C14: =B14/B$22*B$24 -> 0 | E14: =IFERROR(INDEX(Correspondance!$D$2:$D$3000,MATCH(A14,Correspondance!$A$2:$A$3000,0)),0) -> 0 | F14: =C14*E14 -> 0
C15: =B15/B$22*B$24 -> 0 | E15: =IFERROR(INDEX(Correspondance!$D$2:$D$3000,MATCH(A15,Correspondance!$A$2:$A$3000,0)),0) -> 0 | F15: =C15*E15 -> 0
C16: =B16/B$22*B$24 -> 0 | E16: =IFERROR(INDEX(Correspondance!$D$2:$D$3000,MATCH(A16,Correspondance!$A$2:$A$3000,0)),0) -> 0 | F16: =C16*E16 -> 0
C17: =B17/B$22*B$24 -> 0 | E17: =IFERROR(INDEX(Correspondance!$D$2:$D$3000,MATCH(A17,Correspondance!$A$2:$A$3000,0)),0) -> 0 | F17: =C17*E17 -> 0
C18: =B18/B$22*B$24 -> 0 | E18: =IFERROR(INDEX(Correspondance!$D$2:$D$3000,MATCH(A18,Correspondance!$A$2:$A$3000,0)),0) -> 0 | F18: =C18*E18 -> 0
F19: =SUM(F4:F18) -> 86.339
A20: Prix unitaire portion | B20: =F19/B24 -> 0.7849
A21: Poids total ou ingrédient principal | B21: =SUM(B3:B18) -> 7.7
A22: Nombre portions recette base | B22: =B21/B23 -> 70
A23: Poids net portions | B23: 0.11 | C23: Possibilité de saisir le grammage
A24: Nombre portions à produire | B24: =Paramètres!$B$5 -> 110 | C24: Effectif EHPAD + FAM (feuille Paramètres) – possibilité de saisir un autre nombre

Sheet E-Salade d'endives
A1: Salade d'endives | E1: VP Théorique minimum | G1: Préparation froide Bac gastro + film, 0/+3°C
E2: Liaison froide 0/+3°C
A3: Produits | B3: Qté recette base | C3: Qté production | D3: U | E3: PU | F3: Total €
A4: Endives | B4: 5.42 | C4: =B4/B$22*B$24 -> 8.522554 | D4: Kg | E4: =IFERROR(INDEX(Correspondance!$D$2:$D$3000,MATCH(A4,Correspondance!$A$2:$A$3000,0)),0) -> 2.6 | F4: =C4*E4 -> 22.15864 | G4: Mode opératoire : Parer les endives, retirer les premières feuilles et le cône amer à la base Décontaminer, rincer à l'eau claire, égoutter Émincer les endives en tronçons de 1 cm, citronner légèrement pour éviter l'oxydation Vinaigrette : moutarde, sel, poivre, vinaigre, monter à l'huile, ajouter les échalotes Conditionner les endives en bacs gastro filmés, vinaigrette à part Stocker à 0/+3°C, assaisonner et parsemer de persil au moment du service Service en liaison froide, consommation dans les 24h
A5: Huile de tournesol | B5: 0.452 | C5: =B5/B$22*B$24 -> 0.71073698 | D5: L | E5: =IFERROR(INDEX(Correspondance!$D$2:$D$3000,MATCH(A5,Correspondance!$A$2:$A$3000,0)),0) -> 2.2 | F5: =C5*E5 -> 1.5636213
A6: Vinaigre de cidre | B6: 0.136 | C6: =B6/B$22*B$24 -> 0.21385006 | D6: L | E6: =IFERROR(INDEX(Correspondance!$D$2:$D$3000,MATCH(A6,Correspondance!$A$2:$A$3000,0)),0) -> 1.8 | F6: =C6*E6 -> 0.38493011
A7: Moutarde | B7: 0.072 | C7: =B7/B$22*B$24 -> 0.11321474 | D7: Kg | E7: =IFERROR(INDEX(Correspondance!$D$2:$D$3000,MATCH(A7,Correspondance!$A$2:$A$3000,0)),0) -> 9 | F7: =C7*E7 -> 1.0189327
A8: Jus de citron | B8: 0.09 | C8: =B8/B$22*B$24 -> 0.14151842 | D8: L | E8: =IFERROR(INDEX(Correspondance!$D$2:$D$3000,MATCH(A8,Correspondance!$A$2:$A$3000,0)),0) -> 2.5 | F8: =C8*E8 -> 0.35379606
A9: Échalotes ciselées surgelées | B9: 0.09 | C9: =B9/B$22*B$24 -> 0.14151842 | D9: Kg | E9: =IFERROR(INDEX(Correspondance!$D$2:$D$3000,MATCH(A9,Correspondance!$A$2:$A$3000,0)),0) -> 4.5 | F9: =C9*E9 -> 0.63683291
A10: Sel | B10: 0.036 | C10: =B10/B$22*B$24 -> 0.05660737 | D10: Kg | E10: =IFERROR(INDEX(Correspondance!$D$2:$D$3000,MATCH(A10,Correspondance!$A$2:$A$3000,0)),0) -> 2 | F10: =C10*E10 -> 0.11321474
A11: Poivre PM | C11: =B11/B$22*B$24 -> 0 | D11: Kg | E11: =IFERROR(INDEX(Correspondance!$D$2:$D$3000,MATCH(A11,Correspondance!$A$2:$A$3000,0)),0) -> 18 | F11: =C11*E11 -> 0
A12: Persil haché PM | C12: =B12/B$22*B$24 -> 0 | D12: Kg | E12: =IFERROR(INDEX(Correspondance!$D$2:$D$3000,MATCH(A12,Correspondance!$A$2:$A$3000,0)),0) -> 8 | F12: =C12*E12 -> 0
C13: =B13/B$22*B$24 -> 0 | E13: =IFERROR(INDEX(Correspondance!$D$2:$D$3000,MATCH(A13,Correspondance!$A$2:$A$3000,0)),0) -> 0 | F13: =C13*E13 -> 0
C14: =B14/B$22*B$24 -> 0 | E14: =IFERROR(INDEX(Correspondance!$D$2:$D$3000,MATCH(A14,Correspondance!$A$2:$A$3000,0)),0) -> 0 | F14: =C14*E14 -> 0
C15: =B15/B$22*B$24 -> 0 | E15: =IFERROR(INDEX(Correspondance!$D$2:$D$3000,MATCH(A15,Correspondance!$A$2:$A$3000,0)),0) -> 0 | F15: =C15*E15 -> 0
C16: =B16/B$22*B$24 -> 0 | E16: =IFERROR(INDEX(Correspondance!$D$2:$D$3000,MATCH(A16,Correspondance!$A$2:$A$3000,0)),0) -> 0 | F16: =C16*E16 -> 0
C17: =B17/B$22*B$24 -> 0 | E17: =IFERROR(INDEX(Correspondance!$D$2:$D$3000,MATCH(A17,Correspondance!$A$2:$A$3000,0)),0) -> 0 | F17: =C17*E17 -> 0
C18: =B18/B$22*B$24 -> 0 | E18: =IFERROR(INDEX(Correspondance!$D$2:$D$3000,MATCH(A18,Correspondance!$A$2:$A$3000,0)),0) -> 0 | F18: =C18*E18 -> 0
F19: =SUM(F4:F18) -> 26.229968
A20: Prix unitaire portion | B20: =F19/B24 -> 0.23845426
A21: Poids total ou ingrédient principal | B21: =SUM(B3:B18) -> 6.296
A22: Nombre portions recette base | B22: =B21/B23 -> 69.955556
A23: Poids net portions | B23: 0.09 | C23: Possibilité de saisir le grammage
A24: Nombre portions à produire | B24: =Paramètres!$B$5 -> 110 | C24: Effectif EHPAD + FAM (feuille Paramètres) – possibilité de saisir un autre nombre

Sheet E-Salade d'endives aux noix
A1: Salade d'endives aux noix | E1: VP Théorique minimum | G1: Préparation froide Bac gastro + film, 0/+3°C
E2: Liaison froide 0/+3°C
A3: Produits | B3: Qté recette base | C3: Qté production | D3: U | E3: PU | F3: Total €
A4: Endives | B4: 4.95 | C4: =B4/B$22*B$24 -> 7.7852445 | D4: Kg | E4: =IFERROR(INDEX(Correspondance!$D$2:$D$3000,MATCH(A4,Correspondance!$A$2:$A$3000,0)),0) -> 2.6 | F4: =C4*E4 -> 20.241636 | G4: Mode opératoire : Parer les endives, retirer le cône amer, décontaminer, rincer, égoutter Émincer en tronçons de 1 cm, citronner Laver les pommes, tailler en petits dés avec la peau, citronner Concasser grossièrement les cerneaux de noix Vinaigrette : moutarde, sel, poivre, vinaigre, monter aux huiles de noix et de tournesol Mélanger endives et pommes, conditionner en bacs gastro filmés, noix et vinaigrette à part Stocker à 0/+3°C, assaisonner et parsemer de noix au moment du service Service en liaison froide, consommation dans les 24h
A5: Cerneaux de noix | B5: 0.36 | C5: =B5/B$22*B$24 -> 0.5661996 | D5: Kg | E5: =IFERROR(INDEX(Correspondance!$D$2:$D$3000,MATCH(A5,Correspondance!$A$2:$A$3000,0)),0) -> 14 | F5: =C5*E5 -> 7.9267944
A6: Pommes | B6: 0.901 | C6: =B6/B$22*B$24 -> 1.4170718 | D6: Kg | E6: =IFERROR(INDEX(Correspondance!$D$2:$D$3000,MATCH(A6,Correspondance!$A$2:$A$3000,0)),0) -> 1.7 | F6: =C6*E6 -> 2.409022
A7: Huile de noix | B7: 0.18 | C7: =B7/B$22*B$24 -> 0.2830998 | D7: L | E7: =IFERROR(INDEX(Correspondance!$D$2:$D$3000,MATCH(A7,Correspondance!$A$2:$A$3000,0)),0) -> 12 | F7: =C7*E7 -> 3.3971976
A8: Huile de tournesol | B8: 0.27 | C8: =B8/B$22*B$24 -> 0.4246497 | D8: L | E8: =IFERROR(INDEX(Correspondance!$D$2:$D$3000,MATCH(A8,Correspondance!$A$2:$A$3000,0)),0) -> 2.2 | F8: =C8*E8 -> 0.93422934
A9: Vinaigre de cidre | B9: 0.135 | C9: =B9/B$22*B$24 -> 0.21232485 | D9: L | E9: =IFERROR(INDEX(Correspondance!$D$2:$D$3000,MATCH(A9,Correspondance!$A$2:$A$3000,0)),0) -> 1.8 | F9: =C9*E9 -> 0.38218473
A10: Moutarde | B10: 0.072 | C10: =B10/B$22*B$24 -> 0.11323992 | D10: Kg | E10: =IFERROR(INDEX(Correspondance!$D$2:$D$3000,MATCH(A10,Correspondance!$A$2:$A$3000,0)),0) -> 9 | F10: =C10*E10 -> 1.0191593
A11: Jus de citron | B11: 0.09 | C11: =B11/B$22*B$24 -> 0.1415499 | D11: L | E11: =IFERROR(INDEX(Correspondance!$D$2:$D$3000,MATCH(A11,Correspondance!$A$2:$A$3000,0)),0) -> 2.5 | F11: =C11*E11 -> 0.35387475
A12: Sel | B12: 0.036 | C12: =B12/B$22*B$24 -> 0.05661996 | D12: Kg | E12: =IFERROR(INDEX(Correspondance!$D$2:$D$3000,MATCH(A12,Correspondance!$A$2:$A$3000,0)),0) -> 2 | F12: =C12*E12 -> 0.11323992
A13: Poivre PM | C13: =B13/B$22*B$24 -> 0 | D13: Kg | E13: =IFERROR(INDEX(Correspondance!$D$2:$D$3000,MATCH(A13,Correspondance!$A$2:$A$3000,0)),0) -> 18 | F13: =C13*E13 -> 0
C14: =B14/B$22*B$24 -> 0 | E14: =IFERROR(INDEX(Correspondance!$D$2:$D$3000,MATCH(A14,Correspondance!$A$2:$A$3000,0)),0) -> 0 | F14: =C14*E14 -> 0
C15: =B15/B$22*B$24 -> 0 | E15: =IFERROR(INDEX(Correspondance!$D$2:$D$3000,MATCH(A15,Correspondance!$A$2:$A$3000,0)),0) -> 0 | F15: =C15*E15 -> 0
C16: =B16/B$22*B$24 -> 0 | E16: =IFERROR(INDEX(Correspondance!$D$2:$D$3000,MATCH(A16,Correspondance!$A$2:$A$3000,0)),0) -> 0 | F16: =C16*E16 -> 0
C17: =B17/B$22*B$24 -> 0 | E17: =IFERROR(INDEX(Correspondance!$D$2:$D$3000,MATCH(A17,Correspondance!$A$2:$A$3000,0)),0) -> 0 | F17: =C17*E17 -> 0
C18: =B18/B$22*B$24 -> 0 | E18: =IFERROR(INDEX(Correspondance!$D$2:$D$3000,MATCH(A18,Correspondance!$A$2:$A$3000,0)),0) -> 0 | F18: =C18*E18 -> 0
F19: =SUM(F4:F18) -> 36.777338
A20: Prix unitaire portion | B20: =F19/B24 -> 0.33433943
A21: Poids total ou ingrédient principal | B21: =SUM(B3:B18) -> 6.994
A22: Nombre portions recette base | B22: =B21/B23 -> 69.94
A23: Poids net portions | B23: 0.1 | C23: Possibilité de saisir le grammage
A24: Nombre portions à produire | B24: =Paramètres!$B$5 -> 110 | C24: Effectif EHPAD + FAM (feuille Paramètres) – possibilité de saisir un autre nombre

Sheet E-Endives au bleu et aux noix
A1: Endives au bleu et aux noix | E1: VP Théorique minimum | G1: Préparation froide Bac gastro + film, 0/+3°C
E2: Liaison froide 0/+3°C
A3: Produits | B3: Qté recette base | C3: Qté production | D3: U | E3: PU | F3: Total €
A4: Endives | B4: 4.76 | C4: =B4/B$22*B$24 -> 7.4780576 | D4: Kg | E4: =IFERROR(INDEX(Correspondance!$D$2:$D$3000,MATCH(A4,Correspondance!$A$2:$A$3000,0)),0) -> 2.6 | F4: =C4*E4 -> 19.44295 | G4: Mode opératoire : Parer les endives, retirer le cône amer, décontaminer, rincer, égoutter, émincer et citronner Tailler les pommes en dés, citronner Sauce au bleu : écraser le bleu à la fourchette, détendre à la crème, ajouter moutarde, vinaigre, huile, poivre, peu de sel (le bleu est salé) Concasser les noix Mélanger endives et pommes, conditionner en bacs gastro filmés Sauce au bleu et noix à part en pots fermés, stocker le tout à 0/+3°C Au service : napper de sauce au bleu, parsemer de noix Service en liaison froide, consommation dans les 24h
A5: Bleu d'Auvergne | B5: 0.952 | C5: =B5/B$22*B$24 -> 1.4956115 | D5: Kg | E5: =IFERROR(INDEX(Correspondance!$D$2:$D$3000,MATCH(A5,Correspondance!$A$2:$A$3000,0)),0) -> 10.5 | F5: =C5*E5 -> 15.703921
A6: Cerneaux de noix | B6: 0.381 | C6: =B6/B$22*B$24 -> 0.59855882 | D6: Kg | E6: =IFERROR(INDEX(Correspondance!$D$2:$D$3000,MATCH(A6,Correspondance!$A$2:$A$3000,0)),0) -> 14 | F6: =C6*E6 -> 8.3798234
A7: Pommes | B7: 0.761 | C7: =B7/B$22*B$24 -> 1.1955466 | D7: Kg | E7: =IFERROR(INDEX(Correspondance!$D$2:$D$3000,MATCH(A7,Correspondance!$A$2:$A$3000,0)),0) -> 1.7 | F7: =C7*E7 -> 2.0324292
A8: Crème 35% | B8: 0.286 | C8: =B8/B$22*B$24 -> 0.44931187 | D8: L | E8: =IFERROR(INDEX(Correspondance!$D$2:$D$3000,MATCH(A8,Correspondance!$A$2:$A$3000,0)),0) -> 5.5 | F8: =C8*E8 -> 2.4712153
A9: Huile de tournesol | B9: 0.286 | C9: =B9/B$22*B$24 -> 0.44931187 | D9: L | E9: =IFERROR(INDEX(Correspondance!$D$2:$D$3000,MATCH(A9,Correspondance!$A$2:$A$3000,0)),0) -> 2.2 | F9: =C9*E9 -> 0.98848611
A10: Vinaigre de cidre | B10: 0.114 | C10: =B10/B$22*B$24 -> 0.17909634 | D10: L | E10: =IFERROR(INDEX(Correspondance!$D$2:$D$3000,MATCH(A10,Correspondance!$A$2:$A$3000,0)),0) -> 1.8 | F10: =C10*E10 -> 0.32237341
A11: Moutarde | B11: 0.048 | C11: =B11/B$22*B$24 -> 0.075408985 | D11: Kg | E11: =IFERROR(INDEX(Correspondance!$D$2:$D$3000,MATCH(A11,Correspondance!$A$2:$A$3000,0)),0) -> 9 | F11: =C11*E11 -> 0.67868086
A12: Jus de citron | B12: 0.095 | C12: =B12/B$22*B$24 -> 0.14924695 | D12: L | E12: =IFERROR(INDEX(Correspondance!$D$2:$D$3000,MATCH(A12,Correspondance!$A$2:$A$3000,0)),0) -> 2.5 | F12: =C12*E12 -> 0.37311737
A13: Sel | B13: 0.019 | C13: =B13/B$22*B$24 -> 0.02984939 | D13: Kg | E13: =IFERROR(INDEX(Correspondance!$D$2:$D$3000,MATCH(A13,Correspondance!$A$2:$A$3000,0)),0) -> 2 | F13: =C13*E13 -> 0.05969878
A14: Poivre PM | C14: =B14/B$22*B$24 -> 0 | D14: Kg | E14: =IFERROR(INDEX(Correspondance!$D$2:$D$3000,MATCH(A14,Correspondance!$A$2:$A$3000,0)),0) -> 18 | F14: =C14*E14 -> 0
C15: =B15/B$22*B$24 -> 0 | E15: =IFERROR(INDEX(Correspondance!$D$2:$D$3000,MATCH(A15,Correspondance!$A$2:$A$3000,0)),0) -> 0 | F15: =C15*E15 -> 0
C16: =B16/B$22*B$24 -> 0 | E16: =IFERROR(INDEX(Correspondance!$D$2:$D$3000,MATCH(A16,Correspondance!$A$2:$A$3000,0)),0) -> 0 | F16: =C16*E16 -> 0
C17: =B17/B$22*B$24 -> 0 | E17: =IFERROR(INDEX(Correspondance!$D$2:$D$3000,MATCH(A17,Correspondance!$A$2:$A$3000,0)),0) -> 0 | F17: =C17*E17 -> 0
C18: =B18/B$22*B$24 -> 0 | E18: =IFERROR(INDEX(Correspondance!$D$2:$D$3000,MATCH(A18,Correspondance!$A$2:$A$3000,0)),0) -> 0 | F18: =C18*E18 -> 0
F19: =SUM(F4:F18) -> 50.452695
A20: Prix unitaire portion | B20: =F19/B24 -> 0.45866087
A21: Poids total ou ingrédient principal | B21: =SUM(B3:B18) -> 7.702
A22: Nombre portions recette base | B22: =B21/B23 -> 70.018182
A23: Poids net portions | B23: 0.11 | C23: Possibilité de saisir le grammage
A24: Nombre portions à produire | B24: =Paramètres!$B$5 -> 110 | C24: Effectif EHPAD + FAM (feuille Paramètres) – possibilité de saisir un autre nombre

Sheet E-Salade de riz
A1: Salade de riz | E1: VP Théorique minimum | G1: Riz cuit à l'eau puis refroidi en cellule Assemblage en liaison froide Bac gastro + film, 0/+3°C
E2: Liaison froide 0/+3°C
A3: Produits | B3: Qté recette base | C3: Qté production | D3: U | E3: PU | F3: Total €
A4: Riz long étuvé | B4: 2.17 | C4: =B4/B$22*B$24 -> 3.4055404 | D4: Kg | E4: =IFERROR(INDEX(Correspondance!$D$2:$D$3000,MATCH(A4,Correspondance!$A$2:$A$3000,0)),0) -> 1.9 | F4: =C4*E4 -> 6.4705267 | G4: Mode opératoire : Cuire le riz à grande eau salée bouillante 12 à 14 min, égoutter Refroidir immédiatement en cellule (63°C à 10°C en moins de deux heures), réserver à 0/+3°C Décontaminer et tailler les tomates, décongeler les poivrons au froid et égoutter Émietter le thon, couper les œufs durs en quartiers, égoutter le maïs et les olives Vinaigrette : moutarde, sel, poivre, vinaigre, monter à l'huile Mélanger riz froid, légumes, thon, olives et vinaigrette, rectifier l'assaisonnement Conditionner en bacs gastro, décorer avec les œufs et la ciboulette, filmer, étiqueter Stocker à 0/+3°C, service en liaison froide, consommation dans les 48h
A5: Tomates en cubes | B5: 1.63 | C5: =B5/B$22*B$24 -> 2.5580787 | D5: Kg | E5: =IFERROR(INDEX(Correspondance!$D$2:$D$3000,MATCH(A5,Correspondance!$A$2:$A$3000,0)),0) -> 1.5 | F5: =C5*E5 -> 3.8371181
A6: Maïs doux appertisé égoutté | B6: 1.09 | C6: =B6/B$22*B$24 -> 1.710617 | D6: Kg | E6: =IFERROR(INDEX(Correspondance!$D$2:$D$3000,MATCH(A6,Correspondance!$A$2:$A$3000,0)),0) -> 2.2 | F6: =C6*E6 -> 3.7633575
A7: Thon au naturel égoutté | B7: 1.09 | C7: =B7/B$22*B$24 -> 1.710617 | D7: Kg | E7: =IFERROR(INDEX(Correspondance!$D$2:$D$3000,MATCH(A7,Correspondance!$A$2:$A$3000,0)),0) -> 9.5 | F7: =C7*E7 -> 16.250862
A8: Œufs durs écalés pasteurisés | B8: 0.868 | C8: =B8/B$22*B$24 -> 1.3622161 | D8: Kg | E8: =IFERROR(INDEX(Correspondance!$D$2:$D$3000,MATCH(A8,Correspondance!$A$2:$A$3000,0)),0) -> 5.6 | F8: =C8*E8 -> 7.6284104
A9: Poivrons dés surgelés | B9: 0.543 | C9: =B9/B$22*B$24 -> 0.85216978 | D9: Kg | E9: =IFERROR(INDEX(Correspondance!$D$2:$D$3000,MATCH(A9,Correspondance!$A$2:$A$3000,0)),0) -> 3 | F9: =C9*E9 -> 2.5565093
A10: Olives noires dénoyautées | B10: 0.217 | C10: =B10/B$22*B$24 -> 0.34055404 | D10: Kg | E10: =IFERROR(INDEX(Correspondance!$D$2:$D$3000,MATCH(A10,Correspondance!$A$2:$A$3000,0)),0) -> 5.5 | F10: =C10*E10 -> 1.8730472
A11: Huile de tournesol | B11: 0.543 | C11: =B11/B$22*B$24 -> 0.85216978 | D11: L | E11: =IFERROR(INDEX(Correspondance!$D$2:$D$3000,MATCH(A11,Correspondance!$A$2:$A$3000,0)),0) -> 2.2 | F11: =C11*E11 -> 1.8747735
A12: Vinaigre de vin | B12: 0.163 | C12: =B12/B$22*B$24 -> 0.25580787 | D12: L | E12: =IFERROR(INDEX(Correspondance!$D$2:$D$3000,MATCH(A12,Correspondance!$A$2:$A$3000,0)),0) -> 1.5 | F12: =C12*E12 -> 0.38371181
A13: Moutarde | B13: 0.054 | C13: =B13/B$22*B$24 -> 0.084746166 | D13: Kg | E13: =IFERROR(INDEX(Correspondance!$D$2:$D$3000,MATCH(A13,Correspondance!$A$2:$A$3000,0)),0) -> 9 | F13: =C13*E13 -> 0.76271549
A14: Sel | B14: 0.043 | C14: =B14/B$22*B$24 -> 0.067483058 | D14: Kg | E14: =IFERROR(INDEX(Correspondance!$D$2:$D$3000,MATCH(A14,Correspondance!$A$2:$A$3000,0)),0) -> 2 | F14: =C14*E14 -> 0.13496612
A15: Poivre PM | C15: =B15/B$22*B$24 -> 0 | D15: Kg | E15: =IFERROR(INDEX(Correspondance!$D$2:$D$3000,MATCH(A15,Correspondance!$A$2:$A$3000,0)),0) -> 18 | F15: =C15*E15 -> 0
A16: Ciboulette ciselée PM | C16: =B16/B$22*B$24 -> 0 | D16: Kg | E16: =IFERROR(INDEX(Correspondance!$D$2:$D$3000,MATCH(A16,Correspondance!$A$2:$A$3000,0)),0) -> 13 | F16: =C16*E16 -> 0
C17: =B17/B$22*B$24 -> 0 | E17: =IFERROR(INDEX(Correspondance!$D$2:$D$3000,MATCH(A17,Correspondance!$A$2:$A$3000,0)),0) -> 0 | F17: =C17*E17 -> 0
C18: =B18/B$22*B$24 -> 0 | E18: =IFERROR(INDEX(Correspondance!$D$2:$D$3000,MATCH(A18,Correspondance!$A$2:$A$3000,0)),0) -> 0 | F18: =C18*E18 -> 0
F19: =SUM(F4:F18) -> 45.535998
A20: Prix unitaire portion | B20: =F19/B24 -> 0.41396362
A21: Poids total ou ingrédient principal | B21: =SUM(B3:B18) -> 8.411
A22: Nombre portions recette base | B22: =B21/B23 -> 70.091667
A23: Poids net portions | B23: 0.12 | C23: Possibilité de saisir le grammage
A24: Nombre portions à produire | B24: =Paramètres!$B$5 -> 110 | C24: Effectif EHPAD + FAM (feuille Paramètres) – possibilité de saisir un autre nombre

Sheet E-Betteraves vinaigrette
A1: Betteraves vinaigrette sous vide basse température | E1: VP Théorique minimum | G1: Sous vide 90°C four vapeur ou thermoplongeur Poches sous vide, 1H30 à 2H00 Refroidissement cellule, DLC J+5
E2: > à 10 000
A3: Produits | B3: Qté recette base | C3: Qté production | D3: U | E3: PU | F3: Total €
